<?xml version="1.0" encoding="utf-8"?>
<!-- This URDF was automatically created by SolidWorks to URDF Exporter! Originally created by Stephen Brawner (brawner@gmail.com) 
     Commit Version: 1.5.1-0-g916b5db  Build Version: 1.5.7152.31018
     For more information, please see http://wiki.ros.org/sw_urdf_exporter -->
<robot
  name="aam2_description">
  <link
    name="Body_base_link">
    <inertial>
      <origin
        xyz="0.4242 0.00099278 0.26967"
        rpy="0 0 0" />
      <mass
        value="60" />
      <inertia
        ixx="1.6457"
        ixy="0.03728"
        ixz="0.092486"
        iyy="3.4584"
        iyz="0.0033974"
        izz="4.3247" />
    </inertial>
    <visual>
      <origin
        xyz="0 0 0"
        rpy="0 0 0" />
      <geometry>
        <mesh
          filename="package://aam2_description/meshes/Body_base_link.STL" />
      </geometry>
      <material
        name="">
        <color
          rgba="0.79216 0.81961 0.93333 1" />
      </material>
    </visual>
    <collision>
      <origin
        xyz="0 0 0"
        rpy="0 0 0" />
      <geometry>
        <mesh
          filename="package://aam2_description/meshes/Body_base_link.STL" />
      </geometry>
    </collision>
  </link>
  <link
    name="FLWheel_Link">
    <inertial>
      <origin
        xyz="-5.9206E-05 0.0076579 3.5345E-06"
        rpy="0 0 0" />
      <mass
        value="15" />
      <inertia
        ixx="0.50824"
        ixy="-0.0032198"
        ixz="3.4634E-05"
        iyy="0.86224"
        iyz="-7.7661E-06"
        izz="0.50811" />
    </inertial>
    <visual>
      <origin
        xyz="0 0 0"
        rpy="0 0 0" />
      <geometry>
        <mesh
          filename="package://aam2_description/meshes/FLWheel_Link.STL" />
      </geometry>
      <material
        name="">
        <color
          rgba="0.29412 0.29412 0.29412 1" />
      </material>
    </visual>
    <collision>
      <origin
        xyz="0 0 0"
        rpy="0 0 0" />
      <geometry>
        <mesh
          filename="package://aam2_description/meshes/FLWheel_Link.STL" />
      </geometry>
    </collision>
  </link>
  <joint
    name="FL"
    type="continuous">
    <origin
      xyz="0.4793 0.60278 0.26798"
      rpy="0.03675 0 0.0090292" />
    <parent
      link="Body_base_link" />
    <child
      link="FLWheel_Link" />
    <axis
      xyz="0 1 0" />
    <dynamics
      damping="0.01"
      friction="0.1" />
  </joint>
  <link
    name="FRWheel_Link">
    <inertial>
      <origin
        xyz="-5.898E-05 -0.007658 3.3922E-06"
        rpy="0 0 0" />
      <mass
        value="15" />
      <inertia
        ixx="0.50824"
        ixy="0.0032201"
        ixz="3.4667E-05"
        iyy="0.86224"
        iyz="7.5378E-06"
        izz="0.50811" />
    </inertial>
    <visual>
      <origin
        xyz="0 0 0"
        rpy="0 0 0" />
      <geometry>
        <mesh
          filename="package://aam2_description/meshes/FRWheel_Link.STL" />
      </geometry>
      <material
        name="">
        <color
          rgba="0.29412 0.29412 0.29412 1" />
      </material>
    </visual>
    <collision>
      <origin
        xyz="0 0 0"
        rpy="0 0 0" />
      <geometry>
        <mesh
          filename="package://aam2_description/meshes/FRWheel_Link.STL" />
      </geometry>
    </collision>
  </link>
  <joint
    name="FR"
    type="continuous">
    <origin
      xyz="0.4793 -0.60278 0.26798"
      rpy="-0.03675 0 -0.0090292" />
    <parent
      link="Body_base_link" />
    <child
      link="FRWheel_Link" />
    <axis
      xyz="0 1 0" />
    <dynamics
      damping="0.01"
      friction="0.1" />
  </joint>
  <link
    name="RLWheel_link">
    <inertial>
      <origin
        xyz="8.4957E-05 0.0076577 3.5974E-06"
        rpy="0 0 0" />
      <mass
        value="15" />
      <inertia
        ixx="0.50824"
        ixy="0.0034433"
        ixz="3.4444E-05"
        iyy="0.86223"
        iyz="-8.4999E-06"
        izz="0.50811" />
    </inertial>
    <visual>
      <origin
        xyz="0 0 0"
        rpy="0 0 0" />
      <geometry>
        <mesh
          filename="package://aam2_description/meshes/RLWheel_link.STL" />
      </geometry>
      <material
        name="">
        <color
          rgba="0.29412 0.29412 0.29412 1" />
      </material>
    </visual>
    <collision>
      <origin
        xyz="0 0 0"
        rpy="0 0 0" />
      <geometry>
        <mesh
          filename="package://aam2_description/meshes/RLWheel_link.STL" />
      </geometry>
    </collision>
  </link>
  <joint
    name="RL"
    type="continuous">
    <origin
      xyz="-1.1124 0.59 0.26743"
      rpy="0.034908 0 0.0090488" />
    <parent
      link="Body_base_link" />
    <child
      link="RLWheel_link" />
    <axis
      xyz="0 1 0" />
    <dynamics
      damping="0.01"
      friction="0.1" />
  </joint>
  <link
    name="RRWheel_link">
    <inertial>
      <origin
        xyz="8.5143E-05 -0.0076577 3.3794E-06"
        rpy="0 0 0" />
      <mass
        value="15" />
      <inertia
        ixx="0.50825"
        ixy="-0.0034431"
        ixz="3.4517E-05"
        iyy="0.86223"
        iyz="8.1749E-06"
        izz="0.50811" />
    </inertial>
    <visual>
      <origin
        xyz="0 0 0"
        rpy="0 0 0" />
      <geometry>
        <mesh
          filename="package://aam2_description/meshes/RRWheel_link.STL" />
      </geometry>
      <material
        name="">
        <color
          rgba="0.29412 0.29412 0.29412 1" />
      </material>
    </visual>
    <collision>
      <origin
        xyz="0 0 0"
        rpy="0 0 0" />
      <geometry>
        <mesh
          filename="package://aam2_description/meshes/RRWheel_link.STL" />
      </geometry>
    </collision>
  </link>
  <joint
    name="RR"
    type="continuous">
    <origin
      xyz="-1.1124 -0.59 0.26743"
      rpy="-0.034908 0 -0.0090488" />
    <parent
      link="Body_base_link" />
    <child
      link="RRWheel_link" />
    <axis
      xyz="0 1 0" />
    <dynamics
      damping="0.01"
      friction="0.1" />
  </joint>
  <link
    name="lidar_link">
    <inertial>
      <origin
        xyz="-0.053516 -1.8601E-06 -7.0365E-05"
        rpy="0 0 0" />
      <mass
        value="0.61592" />
      <inertia
        ixx="0.0006838"
        ixy="3.8781E-12"
        ixz="-3.1807E-06"
        iyy="0.00069055"
        iyz="-3.8172E-08"
        izz="0.00083911" />
    </inertial>
    <visual>
      <origin
        xyz="0 0 0"
        rpy="0 0 0" />
      <geometry>
        <mesh
          filename="package://aam2_description/meshes/lidar_link.STL" />
      </geometry>
      <material
        name="">
        <color
          rgba="0 0 0 1" />
      </material>
    </visual>
    <collision>
      <origin
        xyz="0 0 0"
        rpy="0 0 0" />
      <geometry>
        <mesh
          filename="package://aam2_description/meshes/lidar_link.STL" />
      </geometry>
    </collision>
  </link>
  <joint
    name="lidar"
    type="fixed">
    <origin
      xyz="1.5436 0 0.33267"
      rpy="0 0 0" />
    <parent
      link="Body_base_link" />
    <child
      link="lidar_link" />
    <axis
      xyz="0 0 0" />
  </joint>
  <link
    name="camera_link">
    <inertial>
      <origin
        xyz="0.4242 0.00099278 0.26967"
        rpy="0 0 0" />
      <mass
        value="75.184" />
      <inertia
        ixx="1.6457"
        ixy="0.03728"
        ixz="0.092486"
        iyy="3.4584"
        iyz="0.0033974"
        izz="4.3247" />
    </inertial>
    <visual>
      <origin
        xyz="0 0 0"
        rpy="0 0 0" />
      <geometry>
        <mesh
          filename="package://aam2_description/meshes/camera_link.STL" />
      </geometry>
      <material
        name="">
        <color
          rgba="0.79216 0.81961 0.93333 1" />
      </material>
    </visual>
    <collision>
      <origin
        xyz="0 0 0"
        rpy="0 0 0" />
      <geometry>
        <mesh
          filename="package://aam2_description/meshes/camera_link.STL" />
      </geometry>
    </collision>
  </link>
  <joint
    name="camera"
    type="fixed">
    <origin
      xyz="-0.501741677782671 -0.00204072303255767 1.245585153331"
      rpy="-0.000146049185555953 -0.0134583610912312 0.0108518311682477" />
    <parent
      link="Body_base_link" />
    <child
      link="camera_link" />
    <axis
      xyz="0 0 0" />
  </joint>

<gazebo reference ="RR">
    <material>Gazebo/Black</material>
</gazebo>

<gazebo reference ="RL">
    <material>Gazebo/Black</material>
</gazebo>

<gazebo reference ="FR">
    <material>Gazebo/Black</material>
</gazebo>

<gazebo reference ="FL">
    <material>Gazebo/Black</material>
</gazebo>

<gazebo>
  <plugin name="gazebo_ros_control" filename= "libgazebo_ros_control.so">
   <robotNamespace>/</robotNamespace>
   <legacyModeNS>true</legacyModeNS>
  </plugin>
</gazebo>

<!-- ............... Diff Drive ............... -->
 <transmission name="rear_left_wheel_trans">
      <type>transmission_interface/SimpleTransmission</type>
      <joint name="RL">
        <hardwareInterface>VelocityJointInterface</hardwareInterface>
      </joint>
      <actuator name="rear_left_wheel_motor">
        <hardwareInterface>EffortJointInterface</hardwareInterface>
        <mechanicalReduction>1</mechanicalReduction>
      </actuator>
    
 </transmission>

 <transmission name="rear_right_wheel_trans">
      <type>transmission_interface/SimpleTransmission</type>
      <joint name="RR">
        <hardwareInterface>VelocityJointInterface</hardwareInterface>
      </joint>
      <actuator name="rear_right_wheel_motor">
        <hardwareInterface>EffortJointInterface</hardwareInterface>
        <mechanicalReduction>1</mechanicalReduction>
      </actuator>
 </transmission>

 <!-- Gazebo requires the velodyne_gazebo_plugins package -->

     <gazebo reference="lidar_link">
      <sensor type="ray" name="velodyne-VLP16">
        <pose>0 0 0 0 0 0</pose>
        <visualize>true</visualize>
        <update_rate>6</update_rate>
        <ray>
          <scan>
            <horizontal>
              <samples>1200</samples>
              <resolution>1</resolution>
              <min_angle>-2</min_angle>
              <max_angle>2</max_angle>
            </horizontal>
            <vertical>
              <samples>5</samples>
              <resolution>1</resolution>
              <min_angle>-0.122</min_angle>
              <max_angle> 0.017</max_angle>
            </vertical>
          </scan>
          <range>
            <min>0.3</min>
            <max>131</max>
            <resolution>0.001</resolution>
          </range>
          <noise>
            <type>gaussian</type>
            <mean>0.0</mean>
            <stddev>0.0</stddev>
          </noise>
        </ray>
        <plugin name="gazebo_ros_laser_controller" filename="libgazebo_ros_velodyne_laser.so">
          <topicName>/velodyne_points</topicName>
          <frameName>lidar_link</frameName>
          <min_range>0.6</min_range>
          <max_range>130</max_range>
          <gaussianNoise>0.008</gaussianNoise>
        </plugin>
      </sensor>
    </gazebo>


<!-- ............... Camera ............... -->

<gazebo reference="camera_link">
    <sensor type="multicamera" name="stereo_camera">
      <update_rate>30.0</update_rate>
      <camera name="left">
        <horizontal_fov>1.3962634</horizontal_fov>
        <image>
          <width>800</width>
          <height>800</height>
          <format>R8G8B8</format>
        </image>
        <clip>
          <near>0.02</near>
          <far>300</far>
        </clip>
        <noise>
          <type>gaussian</type>
          <mean>0.0</mean>
          <stddev>0.007</stddev>
        </noise>
      </camera>
      <camera name="right">
        <pose>0 -0.07 0 0 0 0</pose>
        <horizontal_fov>1.3962634</horizontal_fov>
        <image>
          <width>800</width>
          <height>800</height>
          <format>R8G8B8</format>
        </image>
        <clip>
          <near>0.02</near>
          <far>300</far>
        </clip>
        <noise>
          <type>gaussian</type>
          <mean>0.0</mean>
          <stddev>0.007</stddev>
        </noise>
      </camera>
      <plugin name="stereo_camera_controller" filename="libgazebo_ros_multicamera.so">
        <alwaysOn>true</alwaysOn>
        <updateRate>0.0</updateRate>
        <cameraName>multisense_sl/camera</cameraName>
        <imageTopicName>image_raw</imageTopicName>
        <cameraInfoTopicName>camera_info</cameraInfoTopicName>
        <frameName>left_camera_optical_frame</frameName>
        <!--<rightFrameName>right_camera_optical_frame</rightFrameName>-->
        <hackBaseline>0.07</hackBaseline>
        <distortionK1>0.0</distortionK1>
        <distortionK2>0.0</distortionK2>
        <distortionK3>0.0</distortionK3>
        <distortionT1>0.0</distortionT1>
        <distortionT2>0.0</distortionT2>
      </plugin>
    </sensor>
  </gazebo>

</robot>
